Workbook
Name Slicer_Yrmo: #N/A

Sheet Lookup
A1: For drop down: | G1: Exp - House Maint | H1: House Maintenance | K1: For Personal Capital / Empower
A2: Exp - Rent | B2: Rent | G2: Exp - Utilities | H2: Utilities | K2: Credit Card Payments | L2: Delete
A3: Exp - House Maint | B3: House Maintenance | G3: Exp - Car Loan | H3: Car Loan | K3: Deposits | L3: Delete
A4: Exp - Utilities | B4: Utilities | G4: Exp - Cleaning | H4: Cleaning | K4: Investment Income | L4: Inc - Other
A5: Exp - Car Loan | B5: Car Loan | G5: Exp - Insurance | H5: Insurance | K5: Delete | L5: Delete
A6: Exp - Cleaning | B6: Cleaning | G6: Exp - Day Care | H6: Day Care | K6: Shopping | L6: Shopping
A7: Exp - Insurance | B7: Insurance | G7: Exp - Transportation | H7: Transportation | K7: Paychecks/Salary | L7: Inc - Other
A8: Exp - Day Care | B8: Day Care | G8: Exp - Restaurants | H8: Restaurants | K8: Credit Card Payments | L8: Delete
A9: Exp - Transportation | B9: Transportation | G9: Exp - Groceries | H9: Groceries | K9: Misc | L9: Misc
A10: Exp - Restaurants | B10: Restaurants | G10: Exp - Target | H10: Target | K10: Transfers | L10: Delete
A11: Exp - Groceries | B11: Groceries | G11: Exp - Gym | H11: Gym | K11: Delete - Other Expenses | L11: Delete
A12: Exp - Target | B12: Target | G12: Exp - Shopping | H12: Shopping | K12: Groceries | L12: Groceries
A13: Exp - Gym | B13: Gym | G13: Exp - Amazon | H13: Amazon | K13: Restaurants | L13: Restaurants
... A29: Inc - Other | B29: Inc - Other | G29: Delete | H29: Delete | K29: Car Loan | L29: Car Loan
A30: Inc - Dividend | B30: Dividend | G30: For suggested category: | K30: Healthcare | L30: Healthcare
A31: Delete | B31: Delete | G31: Description | H31: Category
G32: TYPE TRANSFER ID PAYPALSD11 CO PAYPAL ACH ECC PPD ACH Trace 22822 282464808 | H32: Shopping
G33: TYPE TRANSFER ID PAYPALSD11 CO PAYPAL ACH ECC PPD ACH Trace 23715 321924713 | H33: Shopping
G34: TYPE TRANSFER ID PAYPALSD11 CO PAYPAL ACH ECC PPD ACH Trace 96587 311867131 | H34: Shopping
G35: 06 455 Pond Promenade Chanhassen MN | H35: Delete
G36: 11003 NORTH LOOP MINNEAPOLIS MN | H36: Shopping
G37: 11003 NORTH LOOP MINNEAPOLIS MN 248335279 | H37: Shopping
G38: 11003 NORTH LOOP MINNEAPOLIS MN 290461321 | H38: Shopping
G39: 2020 OUTRUN ALD VIRTUA HTTPSRACEROSTMA 313537608 | H39: Gifts
G40: 3 DAY BLINDS LLC 8008003329 CA 283004524 | H40: House Maintenance
G41: 3 DAY BLINDS LLC 8008003329 CA 285992548 | H41: House Maintenance
G42: 47 Cardtronics C2 1301 MAIN ST ALAMOSA CO 326479211 | H42: Shopping
G43: 49 WINCO FOODS 160 2913 Max Aven | H43: Groceries
... G516: Chateau St. Jean | H516: Travel
G517: CHECK 2152
G518: CHECK 2342 | H518: Travel
G519: CHECK 2343 | H519: Shopping
G520: CHECK Processed Check PASSPORT | H520: Travel
G521: CHECK 2089 2089 | H521: Delete
G522: CHECK 2097 2097 | H522: Entertainment
G523: CHECK 2098 2098 | H523: Travel
G524: CHECK 2098 2098 | H524: 0
G525: CHECK 2100 2100 | H525: Delete
G526: CHECK 2103 2103 | H526: Entertainment
G527: CHECK 2103 2103 | H527: 0
...

Sheet Trips
A1: Trip | B1: Start | C1: End
A2: Boston | B2: 45664 | C2: 45666
A3: Ireland | B3: 45677 | C3: 45682
A4: Ireland | B4: 45732 | C4: 45737
A5: Irealnd | B5: 45788 | C5: 45793
A6: Miami | B6: 45804 | C6: 45807
A7: Irealnd | B7: 45872 | C7: 45877
A8: Irealnd | B8: 45950 | C8: 45954

Sheet Actuals
A1: Yrmo | B1: Date | C1: Source | D1: Description | E1: Amount | F1: Category | G1: Suggested Cat Value | H1: Manual Cat Value | I1: Notes | J1: Amount2 | K1: ActiveRule | L1: Desc | M1: LongDesc | N1: InflowOutflow | O1: Short Desc | P1: RuleUsed | Q1: Tag
A2: 201907 | B2: 43648 | C2: Discover | D2: Amazon | E2: 3.97 | F2: Amazon | J2: 3.97 | K2: FALSE | N2: - | O2: =LEFT(Table2[[#This Row],[Description]],75) -> Amazon | P2: Create Rule; and Description='Amazon';Amazon
A3: 201907 | B3: 43648 | C3: Discover More Card | D3: Amazon | E3: 3.97 | F3: Amazon | J3: 3.97 | K3: FALSE | N3: - | O3: =LEFT(Table2[[#This Row],[Description]],75) -> Amazon
A4: 201907 | B4: 43648 | C4: Cash Rewards Visa Signature | D4: Borough | E4: 58.95 | F4: Restaurants | J4: 58.95 | K4: FALSE | N4: - | O4: =LEFT(Table2[[#This Row],[Description]],75) -> Borough | P4: Create Rule; and Description='Borough';Restaurants
A5: 201907 | B5: 43648 | C5: Cash Rewards Visa Signature | D5: Speedway | E5: 28.61 | F5: Transportation | J5: 28.61 | K5: FALSE | N5: - | O5: =LEFT(Table2[[#This Row],[Description]],75) -> Speedway
A6: 201907 | B6: 43648 | C6: Cash Rewards Visa Signature | D6: Transfer from POWERPLUS CHECKING | E6: -606.63 | F6: Delete | J6: 606.63 | K6: FALSE | N6: .+ | O6: =LEFT(Table2[[#This Row],[Description]],75) -> Transfer from POWERPLUS CHECKING
A7: 201907 | B7: 43648 | C7: POWERPLUS | D7: Transfer to Cash Rewards Visa Signature | E7: 606.63 | F7: Delete | J7: 606.63 | K7: FALSE | N7: - | O7: =LEFT(Table2[[#This Row],[Description]],75) -> Transfer to Cash Rewards Visa Signature | P7: Delete; and Description Like '%Transfer to Cash Rewards Visa Signature%';0
A8: 201907 | B8: 43648 | C8: POWERPLUS CHECKING | D8: Transfer to Cash Rewards Visa Signature | E8: 606.63 | F8: Delete | J8: 606.63 | K8: FALSE | N8: - | O8: =LEFT(Table2[[#This Row],[Description]],75) -> Transfer to Cash Rewards Visa Signature
A9: 201907 | B9: 43649 | C9: Discover | D9: Amazon | E9: 115.84 | F9: Amazon | J9: 115.84 | K9: FALSE | N9: - | O9: =LEFT(Table2[[#This Row],[Description]],75) -> Amazon | P9: Create Rule; and Description='Amazon';Amazon
A10: 201907 | B10: 43649 | C10: Discover More Card | D10: Amazon | E10: 115.84 | F10: Amazon | J10: 115.84 | K10: FALSE | N10: - | O10: =LEFT(Table2[[#This Row],[Description]],75) -> Amazon
A11: 201907 | B11: 43649 | C11: POWERPLUS | D11: CCLC TYPE INTERNET ID CO CCLC ACH ECC WEB ACH Trace 49616 233344358 | E11: 247.5 | F11: Day Care | J11: 247.5 | K11: FALSE | N11: - | O11: =LEFT(Table2[[#This Row],[Description]],75) -> CCLC TYPE INTERNET ID CO CCLC ACH ECC WEB ACH Trace 49616 233344358 | P11: Create Rule; and Description Like '%CCLC TYPE INTERNET ID%';Day Care
A12: 201907 | B12: 43649 | C12: POWERPLUS CHECKING | D12: CCLC TYPE INTERNET ID CO CCLC ACH ECC WEB ACH Trace 49616 233344358 | E12: 247.5 | F12: Day Care | J12: 247.5 | K12: FALSE | N12: - | O12: =LEFT(Table2[[#This Row],[Description]],75) -> CCLC TYPE INTERNET ID CO CCLC ACH ECC WEB ACH Trace 49616 233344358
A13: 201907 | B13: 43649 | C13: Cash Rewards Visa Signature | D13: Cub Foods | E13: 125.59 | F13: Groceries | J13: 125.59 | K13: FALSE | N13: - | O13: =LEFT(Table2[[#This Row],[Description]],75) -> Cub Foods
A14: 201907 | B14: 43649 | C14: Cash Rewards Visa Signature | D14: Transfer from POWERPLUS CHECKING | E14: -694.19 | F14: Delete | J14: 694.19 | K14: FALSE | N14: .+ | O14: =LEFT(Table2[[#This Row],[Description]],75) -> Transfer from POWERPLUS CHECKING
A15: 201907 | B15: 43649 | C15: POWERPLUS | D15: Transfer to Cash Rewards Visa Signature | E15: 694.19 | F15: Delete | J15: 694.19 | K15: FALSE | N15: - | O15: =LEFT(Table2[[#This Row],[Description]],75) -> Transfer to Cash Rewards Visa Signature | P15: Delete; and Description Like '%Transfer to Cash Rewards Visa Signature%';0
A16: 201907 | B16: 43649 | C16: POWERPLUS CHECKING | D16: Transfer to Cash Rewards Visa Signature | E16: 694.19 | F16: Delete | J16: 694.19 | K16: FALSE | N16: - | O16: =LEFT(Table2[[#This Row],[Description]],75) -> Transfer to Cash Rewards Visa Signature
A17: 201907 | B17: 43650 | C17: POWERPLUS | D17: Withdrawal Home To Loan Mortgage Payment Thank You 233602111 | E17: 2770.79 | F17: Rent | J17: 2770.79 | K17: FALSE | N17: - | O17: =LEFT(Table2[[#This Row],[Description]],75) -> Withdrawal Home To Loan Mortgage Payment Thank You 233602111 | P17: Create Rule; and Description Like '%Withdrawal Home To Loan Mortgage Payment%';Rent
A18: 201907 | B18: 43650 | C18: POWERPLUS CHECKING | D18: Withdrawal Home To Loan Mortgage Payment Thank You 233602111 | E18: 2770.79 | F18: Rent | J18: 2770.79 | K18: FALSE | N18: - | O18: =LEFT(Table2[[#This Row],[Description]],75) -> Withdrawal Home To Loan Mortgage Payment Thank You 233602111
A19: 201907 | B19: 43650 | C19: Cash Rewards Visa Signature | D19: Cub Foods | E19: 136.89 | F19: Groceries | J19: 136.89 | K19: FALSE | N19: - | O19: =LEFT(Table2[[#This Row],[Description]],75) -> Cub Foods
A20: 201907 | B20: 43650 | C20: Cash Rewards Visa Signature | D20: Dollar Tree | E20: 5.38 | F20: 0 | J20: 5.38 | K20: FALSE | N20: - | O20: =LEFT(Table2[[#This Row],[Description]],75) -> Dollar Tree
A21: 201907 | B21: 43650 | C21: Discover | D21: MIYABI EXCELSIOR MN | E21: 100.23 | F21: 0 | J21: 100.23 | K21: FALSE | N21: - | O21: =LEFT(Table2[[#This Row],[Description]],75) -> MIYABI EXCELSIOR MN
A22: 201907 | B22: 43650 | C22: Discover More Card | D22: MIYABI EXCELSIOR MN | E22: 100.23 | F22: 0 | J22: 100.23 | K22: FALSE | N22: - | O22: =LEFT(Table2[[#This Row],[Description]],75) -> MIYABI EXCELSIOR MN
A23: 201907 | B23: 43650 | C23: Cash Rewards Visa Signature | D23: SHOREWOOD LIQUOR EXCELSIOR MN 233755679 | E23: 9.87 | F23: 0 | J23: 9.87 | K23: FALSE | N23: - | O23: =LEFT(Table2[[#This Row],[Description]],75) -> SHOREWOOD LIQUOR EXCELSIOR MN 233755679
A24: 201907 | B24: 43650 | C24: Cash Rewards Visa Signature | D24: SHOREWOOD LIQUOR EXCELSIOR MN 233755680 | E24: 14.26 | F24: 0 | J24: 14.26 | K24: FALSE | N24: - | O24: =LEFT(Table2[[#This Row],[Description]],75) -> SHOREWOOD LIQUOR EXCELSIOR MN 233755680
A25: 201907 | B25: 43650 | C25: Cash Rewards Visa Signature | D25: SHOREWOOD TRUE VALUE EXCELSIOR MN 233755684 | E25: 33.29 | F25: 0 | J25: 33.29 | K25: FALSE | N25: - | O25: =LEFT(Table2[[#This Row],[Description]],75) -> SHOREWOOD TRUE VALUE EXCELSIOR MN 233755684
A26: 201907 | B26: 43650 | C26: Cash Rewards Visa Signature | D26: SOTA CLOTHING SPENCEDESIGNSMN 233755683 | E26: 114.71 | F26: Shopping | J26: 114.71 | K26: FALSE | N26: - | O26: =LEFT(Table2[[#This Row],[Description]],75) -> SOTA CLOTHING SPENCEDESIGNSMN 233755683
A27: 201907 | B27: 43651 | C27: 30 YR FIXED | D27: PAYMENT 234306694 | E27: -533.82 | F27: 0 | J27: 533.82 | K27: FALSE | N27: .+ | O27: =LEFT(Table2[[#This Row],[Description]],75) -> PAYMENT 234306694
A28: 201907 | B28: 43651 | C28: Target Credit Card | D28: CENTRAL CHECKOUT 79999999187086207507850 | E28: 130.45 | F28: Shopping | J28: 130.45 | K28: FALSE | N28: - | O28: =LEFT(Table2[[#This Row],[Description]],75) -> CENTRAL CHECKOUT 79999999187086207507850
A29: 201907 | B29: 43651 | C29: POWERPLUS | D29: College Savings TYPE ACH ID 550895818 CO College Savings ACH ECC PPD ACH Trace 48247 233797400 | E29: 100 | F29: College Savings | J29: 100 | K29: FALSE | N29: - | O29: =LEFT(Table2[[#This Row],[Description]],75) -> College Savings TYPE ACH ID 550895818 CO College Savings ACH ECC PPD ACH Tr | P29: Create Rule; and Description Like '%College Savings%';College Savings
A30: 201907 | B30: 43651 | C30: POWERPLUS CHECKING | D30: College Savings TYPE ACH ID 550895818 CO College Savings ACH ECC PPD ACH Trace 48247 233797400 | E30: 100 | F30: College Savings | J30: 100 | K30: FALSE | N30: - | O30: =LEFT(Table2[[#This Row],[Description]],75) -> College Savings TYPE ACH ID 550895818 CO College Savings ACH ECC PPD ACH Tr
A31: 201907 | B31: 43651 | C31: POWERPLUS | D31: Deposit by Check Deposit Anywhere check deposit 233928086 | E31: -32.85 | F31: 0 | J31: 32.85 | K31: FALSE | N31: + | O31: =LEFT(Table2[[#This Row],[Description]],75) -> Deposit by Check Deposit Anywhere check deposit 233928086
A32: 201907 | B32: 43651 | C32: POWERPLUS CHECKING | D32: Deposit by Check Deposit Anywhere check deposit 233928086 | E32: -32.85 | F32: 0 | J32: 32.85 | K32: FALSE | N32: .+ | O32: =LEFT(Table2[[#This Row],[Description]],75) -> Deposit by Check Deposit Anywhere check deposit 233928086
A33: 201907 | B33: 43651 | C33: Investor Checking | D33: INST XFER 190704 | E33: 12.99 | F33: 0 | J33: 12.99 | K33: FALSE | N33: - | O33: =LEFT(Table2[[#This Row],[Description]],75) -> INST XFER 190704
A34: 201907 | B34: 43651 | C34: Jeff Roth | D34: SCHWAB S&P 500 INDEX FD | E34: 150 | F34: Delete | J34: 150 | K34: FALSE | N34: - | O34: =LEFT(Table2[[#This Row],[Description]],75) -> SCHWAB S&P 500 INDEX FD | P34: Delete; and Description='SCHWAB S&P 500 INDEX FD' and inflowoutflow='-';0
A35: 201907 | B35: 43651 | C35: Roth Contributory IRA | D35: SCHWAB S&P 500 INDEX FD | E35: 150 | F35: Delete | J35: 150 | K35: FALSE | N35: - | O35: =LEFT(Table2[[#This Row],[Description]],75) -> SCHWAB S&P 500 INDEX FD | P35: Delete; and Description='SCHWAB S&P 500 INDEX FD' and inflowoutflow='-';0
A36: 201907 | B36: 43651 | C36: Jeff Roth | D36: SCHWAB TOTAL STOCK MKT INDEX | E36: 150 | F36: Delete | J36: 150 | K36: FALSE | N36: - | O36: =LEFT(Table2[[#This Row],[Description]],75) -> SCHWAB TOTAL STOCK MKT INDEX | P36: Delete; and Description='SCHWAB TOTAL STOCK MKT INDEX' and inflowoutflow='-';0
A37: 201907 | B37: 43651 | C37: Roth Contributory IRA | D37: SCHWAB TOTAL STOCK MKT INDEX | E37: 150 | F37: Delete | J37: 150 | K37: FALSE | N37: - | O37: =LEFT(Table2[[#This Row],[Description]],75) -> SCHWAB TOTAL STOCK MKT INDEX
A38: 201907 | B38: 43653 | C38: Cash Rewards Visa Signature | D38: Cabin Fever Sporting Goods Inc. | E38: 26.04 | F38: 0 | J38: 26.04 | K38: FALSE | N38: - | O38: =LEFT(Table2[[#This Row],[Description]],75) -> Cabin Fever Sporting Goods Inc.
A39: 201907 | B39: 43653 | C39: Cash Rewards Visa Signature | D39: Cabin Fever Sporting Goods Inc. | E39: 41 | F39: 0 | J39: 41 | K39: FALSE | N39: - | O39: =LEFT(Table2[[#This Row],[Description]],75) -> Cabin Fever Sporting Goods Inc.
A40: 201907 | B40: 43654 | C40: Discover | D40: ALLBIRDS 402-935-7733 CA | E40: 105 | F40: 0 | J40: 105 | K40: FALSE | N40: - | O40: =LEFT(Table2[[#This Row],[Description]],75) -> ALLBIRDS 402-935-7733 CA
...

Sheet Actuals Lookup
A1: Yrmo | B1: Date | C1: Source | D1: Description | E1: Amount | F1: Category
A2: 202301 | B2: 44927 | C2: DISCOVER MORE CARD | D2: AMAZON MUSIC*H06YQ2L23 888-802-3080 WA 2SZOGVT1ISL | E2: 5.36 | F2: Amazon
A3: 202301 | B3: 44927 | C3: Cash Rewards Visa Signature | D3: CARIBOU COFFEE CO #116 REF #001280 | E3: -6.43 | F3: Restaurants
A4: 202301 | B4: 44927 | C4: Cash Rewards Visa Signature | D4: HOME2 SUITES EDEN PRAIRIE REF #031953 | E4: -25 | F4: Travel
A5: 202301 | B5: 44927 | C5: DISCOVER MORE CARD | D5: LUNDS&BYERLYS CHANHAS CHANHASSEN MN | E5: 194.66 | F5: Groceries
A6: 202301 | B6: 44927 | C6: HIGHLANDER | D6: Payments Home Banking Transfer From Share 70 REF # 2402682 | E6: -618.65 | F6: Delete
A7: 202301 | B7: 44927 | C7: Cash Rewards Visa Signature | D7: PIZZA LUCE VI INC 952-767-0854 MN | E7: 57.01 | F7: Restaurants
A8: 202301 | B8: 44927 | C8: POWERPLUS | D8: Withdrawal Home Banking Transfer To Loan 02 REF # 1940599 | E8: 618.65 | F8: Car Loan
A9: 202301 | B9: 44927 | C9: POWERPLUS | D9: Withdrawal Home Banking Transfer To Loan 02 REF # 2402682 | E9: 618.65 | F9: Delete
A10: 202301 | B10: 44928 | C10: Cash Rewards Visa Signature | D10: CUB FOODS #1636 SHOREWOOD MN | E10: 15.66 | F10: Restaurants
A11: 202301 | B11: 44928 | C11: Cash Rewards Visa Signature | D11: HBRSUBSCRIPTION 800-988-0886 MA | E11: 20 | F11: Utilities
A12: 202301 | B12: 44928 | C12: Cash Rewards Visa Signature | D12: SP MINNESOTA ICE MAZE MINNESOTAICEM MN | E12: 84.2 | F12: Entertainment
A13: 202301 | B13: 44929 | C13: DISCOVER MORE CARD | D13: AMZN MKTP US*7B5D40OE3 AMZN.COM/BILLWA 73FWI3OC7KE | E13: 32.2 | F13: Amazon
... A560: 202303 | B560: 45016 | C560: Powerplus - Ending in 8s01 | D560: Discover Bank | E560: -11500 | F560: Delete
A561: 202304 | B561: 45017 | D561: Cleaning | E561: 250 | F561: Cleaning
A562: 202304 | B562: 45017 | C562: Delta Skymiles Platinum - Ending in 1007 | D562: Food Truck Alley Saint Paul Mn 03xkdpv5d3e Xxxxxx0055 | E562: 45.41 | F562: Restaurants
A563: 202304 | B563: 45017 | C563: Delta Skymiles Platinum - Ending in 1007 | D563: Food Truck Alley Saint Paul Mn 03xkdpv5d3e Xxxxxx0055 | E563: -45.41 | F563: Restaurants
A564: 202304 | B564: 45017 | C564: Discover More Card - Ending in 7779 | D564: Publix | E564: 267.01 | F564: Groceries
A565: 202304 | B565: 45017 | C565: Discover More Card - Ending in 7779 | D565: Publix | E565: -267.01 | F565: Groceries
A566: 202304 | B566: 45017 | C566: Delta Skymiles Platinum - Ending in 1007 | D566: Smokin R's Bbq Naples Fl Rqdp9hw5zii Squareup.com/receipts | E566: 41.5 | F566: Restaurants
A567: 202304 | B567: 45017 | C567: Delta Skymiles Platinum - Ending in 1007 | D567: Smokin R's Bbq Naples Fl Rqdp9hw5zii Squareup.com/receipts | E567: -41.5 | F567: Restaurants
A568: 202304 | B568: 45017 | C568: Powerplus - Ending in 8s36 | D568: Withdrawal Home Banking Transfer To Loan 02 REF # 3832345 | E568: 618.65 | F568: Car Loan
A569: 202304 | B569: 45018 | C569: Cash Rewards Visa Signature - Ending in 5977 | D569: Amazon Music*HY9257YF0 888-802-3080 WA REF #24692162V302TS4ZQ | E569: 5.36 | F569: Shopping
A570: 202304 | B570: 45018 | C570: Cash Rewards Visa Signature - Ending in 5976 | D570: AMZN Mktp US*HS8HE9CE0 Amzn.com/billWA REF #24692162V305QQLWQ | E570: 15.96 | F570: Amazon
A571: 202304 | B571: 45018 | C571: Delta Skymiles Platinum - Ending in 1007 | D571: Mcdonald's | E571: 15.85 | F571: Restaurants
A572: 202304 | B572: 45018 | C572: Delta Skymiles Platinum - Ending in 1007 | D572: Mcdonald's | E572: -15.85 | F572: Restaurants
A573: 202304 | B573: 45018 | C573: Cash Rewards Visa Signature - Ending in 5978 | D573: SP NORMAL BRAND LLC THENORMALBRAN CREDIT REF #24492162S000H2HSP | E573: -89 | F573: Entertainment
... A739: 202305 | B739: 45047 | C739: Cash Rewards Visa Signature - Ending in 6005 | D739: AMZN Mktp US*HM40K3AB2 Amzn.com/billWA REF #24692163T33HK4QV6 | E739: 77.98 | F739: Amazon
A740: 202305 | B740: 45047 | D740: Cleaning | E740: 250 | F740: Cleaning
A741: 202305 | B741: 45047 | C741: Cash Rewards Visa Signature - Ending in 6008 | D741: HILTON GARDEN INN BOSTON EAST BOSTON MA REF #24275393RS66HS55Z | E741: 301.15 | F741: Delete
A742: 202305 | B742: 45047 | C742: Cash Rewards Visa Signature - Ending in 6009 | D742: JAXON GREY MINNEAPOLIS MN REF #24269793R2XTA5RDS | E742: 392 | F742: Shopping
A743: 202305 | B743: 45047 | C743: Powerplus - Ending in 8s78 | D743: Payment to American Express | E743: 2631.79 | F743: Delete
A744: 202305 | B744: 45047 | C744: Powerplus - Ending in 8s79 | D744: Payment to Baxter Credit Union | E744: 2606.27 | F744: Rent
A745: 202305 | B745: 45047 | C745: Cash Rewards Visa Signature - Ending in 6004 | D745: SCHEELS EDEN PRAIRIE EDEN PRAIRIE CREDIT REF #74138293TP6Q5W11J | E745: -54 | F745: Shopping
A746: 202305 | B746: 45047 | C746: Powerplus - Ending in 8s82 | D746: Transfer to PayPal | E746: 6.47 | F746: Shopping
A747: 202305 | B747: 45047 | C747: Powerplus - Ending in 8s81 | D747: Transfer to Venmo | E747: 35 | F747: Shopping
A748: 202305 | B748: 45047 | C748: Cash Rewards Visa Signature - Ending in 6007 | D748: TST* Red Cow - 1st Ave 612-238-0050 MN REF #24692163R32YMJV0G | E748: 58.81 | F748: Restaurants
A749: 202305 | B749: 45047 | C749: Powerplus - Ending in 8s80 | D749: Withdrawal ACH College Savings TYPE: ACH ID: XX5818 CO: College Savings Entry Class Code: ACH Trace Number: XX3102 | E749: 500 | F749: Delete
A750: 202305 | B750: 45047 | C750: Powerplus - Ending in 8s77 | D750: Withdrawal Home Banking Transfer To Loan 02 REF # XX4306 | E750: 618.65 | F750: Car Loan
A751: 202305 | B751: 45048 | C751: Cash Rewards Visa Signature - Ending in 5997 | D751: AMZN Mktp US*HM5QO4GT2 Amzn.com/billWA REF #24692163S346Y5WE6 | E751: 82.64 | F751: Amazon
...

Sheet Main 2
C2: ='1 MO'!C2 -> 45992
C4: ="Truitt Financials "&TEXT(C2,"MMMM")&" "&TEXT(C2,"YYYY") -> Truitt Financials December 2025
Q7: Budget | R7: Actual
C8: Spending
C9: Monthly Budget: | D9: ='1 MO'!D35 -> 13150 | H9: YTD Budget: | I9: =YTD!D31 -> 157800 | P9: Healthcare | Q9: ='2025 Budget'!O31 -> 2400 | R9: =YTD!C33 -> 3948.01
C10: Spend | D10: ='1 MO'!C35 -> 12529.33 | H10: YTD Spend: | I10: =YTD!C31 -> 164559.5 | P10: House | Q10: ='2025 Budget'!O32 -> 81132 | R10: =YTD!C34 -> 265799.33
P11: Travel | Q11: ='2025 Budget'!O33 -> 13500 | R11: =YTD!C35 -> 16470.36
P14: Financial Goals:
P15: Pay for Cooper & Tuckers college
P16: Retire comfortably
P17: Update house
P18: Stay in budget & reduce stress around finances
P21: 2023 | Q21: -27700
P22: 2022 | Q22: 371119
C23: Yearly Spend Budget: | D23: ='2025 Budget'!O34 -> 97032 | H23: Total Year Budget: | I23: ='2025 Budget'!O36 -> 254832 | P23: 2021 | Q23: 327571
C24: Yearly Spend: | D24: =YTD!C36 -> 286217.7 | H24: Reforecast Budget: | I24: =Revised!P47 -> 450777.2 | P24: 2020 | Q24: 253416
P25: 2019 | Q25: 229415
P26: 2018 | Q26: 188488
P27: 2017 | Q27: 149370
C37: Income | H37: Savings
C38: Projected | D38: ='Main Detail'!D42 -> 391496.07 | H38: Projected | I38: ='Main Detail'!D69 -> 112569
C39: Actual | D39: ='Main Detail'!D51 -> 496800.83 | H39: Actual | I39: ='Main Detail'!D89 -> 117472
C52: Outlook
C80: Balance Sheet
C84: Assets | D84: =EOMONTH(C2,0) -> 46022 | E84: 45657 | F84: $Δ | G84: %Δ
C85: Schwab | D85: 533442.75 | E85: 563767.81 | F85: =D85-E85 -> -30325.06 | G85: =(D85-E85)/E85 -> -0.053789981
C86: Voya (Fidelity) 401K | D86: 555402.24 | E86: 448660.4 | F86: =D86-E86 -> 106741.84 | G86: =(D86-E86)/E86 -> 0.23791233
C87: Vanguard 401K | D87: 511072.69 | E87: 397733.35 | F87: =D87-E87 -> 113339.34 | G87: =(D87-E87)/E87 -> 0.28496313 | M87: *estimated, not available | Q87: CARGILL PARTNERSHIP PLAN
C88: BCU | D88: 19355.62 | E88: 22997 | F88: =D88-E88 -> -3641.38 | G88: =(D88-E88)/E88 -> -0.15834152 | Q88: CARGILL EMPLOYEE RETIREMENT ACCOUNT
C89: HSA | D89: =12330.52+8282.39 -> 20612.91 | E89: 15167.42 | F89: =D89-E89 -> 5445.49 | G89: =(D89-E89)/E89 -> 0.35902546
C90: Discover | D90: 5682.5 | E90: 77311.72 | F90: =D90-E90 -> -71629.22 | G90: =(D90-E90)/E90 -> -0.92649885
C91: Cargill | D91: 32232.83 | E91: 23000 | F91: =D91-E91 -> 9232.83 | G91: =(D91-E91)/E91 -> 0.40142739
C92: House | D92: =705400*0.94 -> 663076 | E92: 659128 | F92: =D92-E92 -> 3948 | G92: =(D92-E92)/E92 -> 0.0059897319
C93: Highlander | D93: =19766*0.9 -> 17789.4 | E93: 17789.4 | F93: =D93-E93 -> 0 | G93: =(D93-E93)/E93 -> 0
C94: BMW | D94: 7114 | E94: 7114 | F94: =D94-E94 -> 0 | G94: =(D94-E94)/E94 -> 0
C95: Total | D95: =SUM(D85:D94) -> 2365780.9 | E95: 2232669.1 | F95: =D95-E95 -> 133111.84 | G95: =(D95-E95)/E95 -> 0.059620048
C97: Liabilities
C98: House | D98: 358864.86 | E98: 368980.21 | F98: =D98-E98 -> -10115.35 | G98: =(D98-E98)/E98 -> -0.027414343
C99: Total | D99: =SUM(D98:D98) -> 358864.86 | E99: 368980.21 | F99: =D99-E99 -> -10115.35 | G99: =(D99-E99)/E99 -> -0.027414343
Q100: Kelly Blue Book
...

Sheet Cash
B2: Steps:
B3: (1) Update cash postions / bonus
B4: (2) Sell stock / remove Sell Stock amount / Update cash positions
B5: (3) Change future Sell Stock values to cover all cost
B7: Kitchen Cost | C7: 189000
B10: Cash
B11: Discover | C11: 0
B12: BCU | C12: 71347 | D12: cash here but need for buffer/operating
B13: Schwab | C13: 0
C14: =SUM(C11:C13) -> 71347
B16: Cash | C16: Date
K17: 25% on signing, 25% the third week in July, 25% the second week in August and 25% at the end of August.
K19: Payment Schedule
K20: Date
B21: Sell stock | C21: Sell Stock | D21: Brit Bonus | E21: Total | F21: Pmt | K21: sign | L21: 43250 | M21: paid
B22: 45779 | C22: =IF(B22<TODAY(),0,6000) -> 0 | E22: =C14 -> 71347 | K22: 45852 | L22: 43250 | M22: paid
B23: =B22+7 -> 45786 | C23: =IF(B23<TODAY(),0,6000) -> 0 | E23: =E22+SUM(C23:D23)-F23 -> 71347 | K23: Furniture | L23: 20000
B24: =B23+7 -> 45793 | C24: =IF(B24<TODAY(),0,6000) -> 0 | E24: =E23+SUM(C24:D24)-F24 -> 71347 | K24: 45902 | L24: 43250
B25: =B24+7 -> 45800 | C25: =IF(B25<TODAY(),0,6000) -> 0 | E25: =E24+SUM(C25:D25)-F25 -> 71347 | K25: 45914 | L25: 43250
B26: =B25+7 -> 45807 | C26: =IF(B26<TODAY(),0,6000) -> 0 | E26: =E25+SUM(C26:D26)-F26 -> 71347 | K26: Italy | L26: 10000
B27: =B26+7 -> 45814 | C27: =IF(B27<TODAY(),0,6000) -> 0 | E27: =E26+SUM(C27:D27)-F27 -> 71347
B28: =B27+7 -> 45821 | C28: =IF(B28<TODAY(),0,6000) -> 0 | E28: =E27+SUM(C28:D28)-F28 -> 71347
B29: =B28+7 -> 45828 | C29: =IF(B29<TODAY(),0,6000) -> 0 | E29: =E28+SUM(C29:D29)-F29 -> 71347
B30: =B29+7 -> 45835 | E30: =E29+SUM(C30:D30)-F30 -> 71347
B31: =B30+7 -> 45842 | E31: =E30+SUM(C31:D31)-F31 -> 71347
B32: =B31+7 -> 45849 | E32: =E31+SUM(C32:D32)-F32 -> 71347
B33: =B32+7 -> 45856 | E33: =E32+SUM(C33:D33)-F33 -> 71347
B34: =B33+7 -> 45863 | E34: =E33+SUM(C34:D34)-F34 -> 71347
B35: =B34+7 -> 45870 | D35: =D17 -> 0 | E35: =E34+SUM(C35:D35)-F35 -> 71347
B36: =B35+7 -> 45877 | E36: =E35+SUM(C36:D36)-F36 -> 71347
B37: =B36+7 -> 45884 | E37: =E36+SUM(C37:D37)-F37 -> 71347
B38: =B37+7 -> 45891 | E38: =E37+SUM(C38:D38)-F38 -> 71347
B39: =B38+7 -> 45898 | E39: =E38+SUM(C39:D39)-F39 -> 71347
B40: =B39+7 -> 45905 | C40: 9000 | E40: =E39+SUM(C40:D40)-F40 -> 37097 | F40: =L24 -> 43250
B41: =B40+7 -> 45912 | C41: 9000 | E41: =E40+SUM(C41:D41)-F41 -> 26097 | F41: =L23 -> 20000
B42: =B41+7 -> 45919 | C42: 9000 | E42: =E41+SUM(C42:D42)-F42 -> 35097
B43: =B42+7 -> 45926 | C43: 9000 | E43: =E42+SUM(C43:D43)-F43 -> 847 | F43: =L25 -> 43250
B44: =B43+7 -> 45933 | C44: 9000 | E44: =E43+SUM(C44:D44)-F44 -> 9847
B45: =B44+7 -> 45940 | E45: =E44+SUM(C45:D45)-F45 -> -153 | F45: =L26 -> 10000
B46: =B45+7 -> 45947 | E46: =E45+SUM(C46:D46)-F46 -> -153

Sheet Main Detail
T4: Projection Waterfall | U4: Actual Waterfall
R5: Income | S5: Income | T5: =D42 -> 391496.07 | U5: =D51 -> 496800.83
R6: Tax | S6: Tax | T6: =-D30 -> -109618.9 | U6: =-U5*D92 -> -144072.24
R7: Expenses | S7: Expenses | T7: =-'2025 Budget'!O36 -> -254832 | U7: =-Revised!P47 -> -450777.2
R8: Savings | S8: Savings | T8: =-D69 -> -112569 | U8: =-D89 -> -117472
R9: Left Over | S9: Left Over | T9: =-SUM(T5:T8) -> 85523.83 | U9: =-SUM(U5:U8) -> 215520.61
X11: Projection | Y11: Actual
S12: Tax | T12: =-T6 -> 109618.9 | U12: =-U6 -> 144072.24 | W12: Tax | X12: =T12/$T$5 -> 0.28 | Y12: =U12/$U$5 -> 0.29
S13: Expenses | T13: =-T7 -> 254832 | U13: =-U7 -> 450777.2 | W13: Expenses | X13: =T13/$T$5 -> 0.65091841 | Y13: =U13/$U$5 -> 0.90736
S14: Savings | T14: =-T8 -> 112569 | U14: =-U8 -> 117472 | W14: Savings | X14: =T14/$T$5 -> 0.28753545 | Y14: =U14/$U$5 -> 0.23645693
S15: Left Over | T15: =-T9 -> -85523.83 | U15: =-U9 -> -215520.61 | W15: Left Over | X15: =T15/$T$5 -> -0.21845386 | Y15: =U15/$U$5 -> -0.43381693
C21: Assumptions
C27: Simple Percentages | D27: Projected | E27: Actual
C28: Income | D28: =D42 -> 391496.07 | E28: =D51 -> 496800.83
C29: Tax % | D29: 0.28 | E29: 0.28
C30: Tax $ | D30: =D28*D29 -> 109618.9 | E30: =E28*E29 -> 139104.23
C31: Savings % | D31: 0.28 | E31: 0.28
C32: Savings $ | D32: =D31*D28 -> 109618.9 | E32: =E31*E28 -> 139104.23
C33: Leftover for Spending | D33: =D28-D30-D32 -> 172258.27 | E33: =E28-E30-E32 -> 218592.37
C37: Income Projection
C38: Brit Salary | D38: 160000
C39: Brit Bonus | D39: 25000
C40: Jeff Salary | D40: 181496.07
C41: Jeff Bonus | D41: 25000
C42: Total | D42: =SUM(D38:D41) -> 391496.07
C44: Income Actual | D44: Total | E44: Jan | F44: Feb | G44: Mar | H44: Apr | I44: May | J44: Jun | K44: Jul | L44: Aug | M44: Sep | N44: Oct | O44: Nov | P44: Dec
C45: Brit Salary | D45: =SUM(E45:P45) -> 172000 | E45: =172000/12 -> 14333.333 | F45: =172000/12 -> 14333.333 | G45: =172000/12 -> 14333.333 | H45: =172000/12 -> 14333.333 | I45: =172000/12 -> 14333.333 | J45: =172000/12 -> 14333.333 | K45: =172000/12 -> 14333.333 | L45: =172000/12 -> 14333.333 | ... P45: =172000/12 -> 14333.333
C46: Brit Bonus | D46: =SUM(E46:P46) -> 50000 | L46: 50000
C47: Brit Stock | D47: =SUM(E47:P47) -> 55000 | L47: 55000
C48: Jeff Salary | D48: =SUM(E48:P48) -> 187725 | E48: =187725/12 -> 15643.75 | F48: =187725/12 -> 15643.75 | G48: =187725/12 -> 15643.75 | H48: =187725/12 -> 15643.75 | I48: =187725/12 -> 15643.75 | J48: =187725/12 -> 15643.75 | K48: =187725/12 -> 15643.75 | L48: =187725/12 -> 15643.75 | ... P48: =187725/12 -> 15643.75
C49: Jeff Bonus | D49: =SUM(E49:P49) -> 32075.83 | G49: =32075.83 -> 32075.83
C50: Inheritance | D50: =SUM(E50:P50) -> 0
C51: Total | D51: =SUM(D45:D50) -> 496800.83
C54: Savings Projection | D54: Total
C55: Brit - 401K | D55: 23500 | E55: =D55/D45 -> 0.13662791
C56: Brit - Traditional IRA | D56: 7000
C57: Brit -Brokerage | D57: 5200
C58: Jeff - 401K | D58: 23500 | E58: =D58/D48 -> 0.12518311
C59: Jeff - Traditional IRA | D59: 7000
C60: Jeff - Brokerage | D60: 14400
...

Sheet 1 MO
B1: Yrmo | C1: 202512
C2: =DATE(LEFT(C1,4),RIGHT(C1,2),1) -> 45992
B3: Year | C3: =LEFT(C1,4) -> 2025
B9: =TEXT(C2,"MMMM YYYY") -> December 2025 | C9: Actual | D9: Budget | E9: Over/(Under)
B11: Rent | C11: =SUMIFS(Actuals!E:E,Actuals!A:A,'1 MO'!$C$1,Actuals!$F:$F,'1 MO'!B11) -> 3378.51 | D11: =INDEX('2025 Budget'!$B$3:$N$36,MATCH('1 MO'!B11,'2025 Budget'!$B$3:$B$36,0),MATCH('1 MO'!$C$1,'2025 Budget'!$B$3:$N$3,0)) -> 2745 | E11: =C11-D11 -> 633.51
B12: House Maintenance | C12: =SUMIFS(Actuals!E:E,Actuals!A:A,'1 MO'!$C$1,Actuals!$F:$F,'1 MO'!B12) -> 32.64 | D12: =INDEX('2025 Budget'!$B$3:$N$36,MATCH('1 MO'!B12,'2025 Budget'!$B$3:$B$36,0),MATCH('1 MO'!$C$1,'2025 Budget'!$B$3:$N$3,0)) -> 350 | E12: =C12-D12 -> -317.36
B13: Utilities | C13: =SUMIFS(Actuals!E:E,Actuals!A:A,'1 MO'!$C$1,Actuals!$F:$F,'1 MO'!B13) -> 1190.87 | D13: =INDEX('2025 Budget'!$B$3:$N$36,MATCH('1 MO'!B13,'2025 Budget'!$B$3:$B$36,0),MATCH('1 MO'!$C$1,'2025 Budget'!$B$3:$N$3,0)) -> 700 | E13: =C13-D13 -> 490.87
B14: Car Loan | C14: =SUMIFS(Actuals!E:E,Actuals!A:A,'1 MO'!$C$1,Actuals!$F:$F,'1 MO'!B14) -> 0 | D14: =INDEX('2025 Budget'!$B$3:$N$36,MATCH('1 MO'!B14,'2025 Budget'!$B$3:$B$36,0),MATCH('1 MO'!$C$1,'2025 Budget'!$B$3:$N$3,0)) -> 0 | E14: =C14-D14 -> 0
B15: Cleaning | C15: =SUMIFS(Actuals!E:E,Actuals!A:A,'1 MO'!$C$1,Actuals!$F:$F,'1 MO'!B15) -> 0 | D15: =INDEX('2025 Budget'!$B$3:$N$36,MATCH('1 MO'!B15,'2025 Budget'!$B$3:$B$36,0),MATCH('1 MO'!$C$1,'2025 Budget'!$B$3:$N$3,0)) -> 250 | E15: =C15-D15 -> -250
B16: Insurance | C16: =SUMIFS(Actuals!E:E,Actuals!A:A,'1 MO'!$C$1,Actuals!$F:$F,'1 MO'!B16) -> 0 | D16: =INDEX('2025 Budget'!$B$3:$N$36,MATCH('1 MO'!B16,'2025 Budget'!$B$3:$B$36,0),MATCH('1 MO'!$C$1,'2025 Budget'!$B$3:$N$3,0)) -> 135 | E16: =C16-D16 -> -135
B17: Day Care | C17: =SUMIFS(Actuals!E:E,Actuals!A:A,'1 MO'!$C$1,Actuals!$F:$F,'1 MO'!B17) -> 495 | D17: =INDEX('2025 Budget'!$B$3:$N$36,MATCH('1 MO'!B17,'2025 Budget'!$B$3:$B$36,0),MATCH('1 MO'!$C$1,'2025 Budget'!$B$3:$N$3,0)) -> 2275 | E17: =C17-D17 -> -1780
B18: Total Rent & Utilitites | C18: =SUM(C11:C17) -> 5097.02 | D18: =SUM(D11:D17) -> 6455 | E18: =C18-D18 -> -1357.98
B20: Transportation | C20: =SUMIFS(Actuals!E:E,Actuals!A:A,'1 MO'!$C$1,Actuals!$F:$F,'1 MO'!B20) -> 225.45 | D20: =INDEX('2025 Budget'!$B$3:$N$36,MATCH('1 MO'!B20,'2025 Budget'!$B$3:$B$36,0),MATCH('1 MO'!$C$1,'2025 Budget'!$B$3:$N$3,0)) -> 400 | E20: =C20-D20 -> -174.55
B21: Restaurants | C21: =SUMIFS(Actuals!E:E,Actuals!A:A,'1 MO'!$C$1,Actuals!$F:$F,'1 MO'!B21) -> 1564.61 | D21: =INDEX('2025 Budget'!$B$3:$N$36,MATCH('1 MO'!B21,'2025 Budget'!$B$3:$B$36,0),MATCH('1 MO'!$C$1,'2025 Budget'!$B$3:$N$3,0)) -> 1300 | E21: =C21-D21 -> 264.61
B22: Groceries | C22: =SUMIFS(Actuals!E:E,Actuals!A:A,'1 MO'!$C$1,Actuals!$F:$F,'1 MO'!B22) -> 1139.06 | D22: =INDEX('2025 Budget'!$B$3:$N$36,MATCH('1 MO'!B22,'2025 Budget'!$B$3:$B$36,0),MATCH('1 MO'!$C$1,'2025 Budget'!$B$3:$N$3,0)) -> 1000 | E22: =C22-D22 -> 139.06
B23: Target | C23: =SUMIFS(Actuals!E:E,Actuals!A:A,'1 MO'!$C$1,Actuals!$F:$F,'1 MO'!B23) -> 818.16 | D23: =INDEX('2025 Budget'!$B$3:$N$36,MATCH('1 MO'!B23,'2025 Budget'!$B$3:$B$36,0),MATCH('1 MO'!$C$1,'2025 Budget'!$B$3:$N$3,0)) -> 675 | E23: =C23-D23 -> 143.16
B24: Total Food & Car | C24: =SUM(C20:C23) -> 3747.28 | D24: =SUM(D20:D23) -> 3375 | E24: =SUM(E20:E23) -> 372.28
B26: Gym | C26: =SUMIFS(Actuals!E:E,Actuals!A:A,'1 MO'!$C$1,Actuals!$F:$F,'1 MO'!B26) -> 0 | D26: =INDEX('2025 Budget'!$B$3:$N$36,MATCH('1 MO'!B26,'2025 Budget'!$B$3:$B$36,0),MATCH('1 MO'!$C$1,'2025 Budget'!$B$3:$N$3,0)) -> 0 | E26: =C26-D26 -> 0
B27: Shopping | C27: =SUMIFS(Actuals!E:E,Actuals!A:A,'1 MO'!$C$1,Actuals!$F:$F,'1 MO'!B27) -> 1902.83 | D27: =INDEX('2025 Budget'!$B$3:$N$36,MATCH('1 MO'!B27,'2025 Budget'!$B$3:$B$36,0),MATCH('1 MO'!$C$1,'2025 Budget'!$B$3:$N$3,0)) -> 2000 | E27: =C27-D27 -> -97.17
B28: Amazon | C28: =SUMIFS(Actuals!E:E,Actuals!A:A,'1 MO'!$C$1,Actuals!$F:$F,'1 MO'!B28) -> 1212.46 | D28: =INDEX('2025 Budget'!$B$3:$N$36,MATCH('1 MO'!B28,'2025 Budget'!$B$3:$B$36,0),MATCH('1 MO'!$C$1,'2025 Budget'!$B$3:$N$3,0)) -> 580 | E28: =C28-D28 -> 632.46
B29: Entertainment | C29: =SUMIFS(Actuals!E:E,Actuals!A:A,'1 MO'!$C$1,Actuals!$F:$F,'1 MO'!B29) -> 278.84 | D29: =INDEX('2025 Budget'!$B$3:$N$36,MATCH('1 MO'!B29,'2025 Budget'!$B$3:$B$36,0),MATCH('1 MO'!$C$1,'2025 Budget'!$B$3:$N$3,0)) -> 550 | E29: =C29-D29 -> -271.16
B30: Dry Cleaning | C30: =SUMIFS(Actuals!E:E,Actuals!A:A,'1 MO'!$C$1,Actuals!$F:$F,'1 MO'!B30) -> 0 | D30: =INDEX('2025 Budget'!$B$3:$N$36,MATCH('1 MO'!B30,'2025 Budget'!$B$3:$B$36,0),MATCH('1 MO'!$C$1,'2025 Budget'!$B$3:$N$3,0)) -> 45 | E30: =C30-D30 -> -45
B31: Gifts | C31: =SUMIFS(Actuals!E:E,Actuals!A:A,'1 MO'!$C$1,Actuals!$F:$F,'1 MO'!B31) -> 282.75 | D31: =INDEX('2025 Budget'!$B$3:$N$36,MATCH('1 MO'!B31,'2025 Budget'!$B$3:$B$36,0),MATCH('1 MO'!$C$1,'2025 Budget'!$B$3:$N$3,0)) -> 100 | E31: =C31-D31 -> 182.75
B32: Misc | C32: =SUMIFS(Actuals!E:E,Actuals!A:A,'1 MO'!$C$1,Actuals!$F:$F,'1 MO'!B32) -> 8.15 | D32: =INDEX('2025 Budget'!$B$3:$N$36,MATCH('1 MO'!B32,'2025 Budget'!$B$3:$B$36,0),MATCH('1 MO'!$C$1,'2025 Budget'!$B$3:$N$3,0)) -> 45 | E32: =C32-D32 -> -36.85
B33: Total Other | C33: =SUM(C26:C32) -> 3685.03 | D33: =SUM(D26:D32) -> 3320 | E33: =C33-D33 -> 365.03
B35: Total | C35: =SUM(C33,C24,C18) -> 12529.33 | D35: =SUM(D33,D24,D18) -> 13150 | E35: =C35-D35 -> -620.67
B37: Healthcare | C37: =SUMIFS(Actuals!E:E,Actuals!A:A,'1 MO'!$C$1,Actuals!$F:$F,'1 MO'!B37) -> 1285.7
B38: House | C38: =SUMIFS(Actuals!E:E,Actuals!A:A,'1 MO'!$C$1,Actuals!$F:$F,'1 MO'!B38) -> 0
B39: Travel | C39: =SUMIFS(Actuals!E:E,Actuals!A:A,'1 MO'!$C$1,Actuals!$F:$F,'1 MO'!B39) -> 1788.34
B40: Total | C40: =SUM(C37:C39) -> 3074.04
B42: Total Spend | C42: =SUM(C40,C35) -> 15603.37

Sheet YTD
B1: Yrmo | C1: ='1 MO'!C1 -> 202512 | G1: =LEFT(C1,4)-1&RIGHT(C1,2) -> 202412
C2: =DATE(LEFT(C1,4),RIGHT(C1,2),1) -> 45992
B3: Jan | C3: =LEFT(C1,4)&"01" -> 202501 | G3: =LEFT(C3,4)-1&RIGHT(C3,2) -> 202401
B5: ="YTD "&TEXT(C2,"MMMM YYYY") -> YTD December 2025 | C5: Actual | D5: Budget | E5: Over/(Under) | G5: Prev Year | H5: Over/(Under)
B7: Rent | C7: =SUMIFS(Actuals!E:E,Actuals!A:A,"<="&YTD!$C$1,Actuals!A:A,">="&YTD!$C$3,Actuals!$F:$F,YTD!B7) -> 34502.09 | D7: =SUMIFS('2025 Budget'!S:S,'2025 Budget'!Q:Q,YTD!B7,'2025 Budget'!R:R,"<="&YTD!$C$1,'2025 Budget'!R:R,">="&YTD!$C$3) -> 32940 | E7: =C7-D7 -> 1562.09 | G7: =SUMIFS(Actuals!E:E,Actuals!A:A,"<="&YTD!$G$1,Actuals!A:A,">="&YTD!$G$3,Actuals!$F:$F,YTD!B7) -> 32915.64 | H7: =C7-G7 -> 1586.45
B8: House Maintenance | C8: =SUMIFS(Actuals!E:E,Actuals!A:A,"<="&YTD!$C$1,Actuals!A:A,">="&YTD!$C$3,Actuals!$F:$F,YTD!B8) -> 4152.49 | D8: =SUMIFS('2025 Budget'!S:S,'2025 Budget'!Q:Q,YTD!B8,'2025 Budget'!R:R,"<="&YTD!$C$1,'2025 Budget'!R:R,">="&YTD!$C$3) -> 4200 | E8: =C8-D8 -> -47.51 | G8: =SUMIFS(Actuals!E:E,Actuals!A:A,"<="&YTD!$G$1,Actuals!A:A,">="&YTD!$G$3,Actuals!$F:$F,YTD!B8) -> 4195.69 | H8: =C8-G8 -> -43.2
B9: Utilities | C9: =SUMIFS(Actuals!E:E,Actuals!A:A,"<="&YTD!$C$1,Actuals!A:A,">="&YTD!$C$3,Actuals!$F:$F,YTD!B9) -> 20671.47 | D9: =SUMIFS('2025 Budget'!S:S,'2025 Budget'!Q:Q,YTD!B9,'2025 Budget'!R:R,"<="&YTD!$C$1,'2025 Budget'!R:R,">="&YTD!$C$3) -> 8400 | E9: =C9-D9 -> 12271.47 | G9: =SUMIFS(Actuals!E:E,Actuals!A:A,"<="&YTD!$G$1,Actuals!A:A,">="&YTD!$G$3,Actuals!$F:$F,YTD!B9) -> 8490 | H9: =C9-G9 -> 12181.47
B10: Car Loan | C10: =SUMIFS(Actuals!E:E,Actuals!A:A,"<="&YTD!$C$1,Actuals!A:A,">="&YTD!$C$3,Actuals!$F:$F,YTD!B10) -> 0 | D10: =SUMIFS('2025 Budget'!S:S,'2025 Budget'!Q:Q,YTD!B10,'2025 Budget'!R:R,"<="&YTD!$C$1,'2025 Budget'!R:R,">="&YTD!$C$3) -> 0 | E10: =C10-D10 -> 0 | G10: =SUMIFS(Actuals!E:E,Actuals!A:A,"<="&YTD!$G$1,Actuals!A:A,">="&YTD!$G$3,Actuals!$F:$F,YTD!B10) -> 0 | H10: =C10-G10 -> 0
B11: Cleaning | C11: =SUMIFS(Actuals!E:E,Actuals!A:A,"<="&YTD!$C$1,Actuals!A:A,">="&YTD!$C$3,Actuals!$F:$F,YTD!B11) -> 241.71 | D11: =SUMIFS('2025 Budget'!S:S,'2025 Budget'!Q:Q,YTD!B11,'2025 Budget'!R:R,"<="&YTD!$C$1,'2025 Budget'!R:R,">="&YTD!$C$3) -> 3000 | E11: =C11-D11 -> -2758.29 | G11: =SUMIFS(Actuals!E:E,Actuals!A:A,"<="&YTD!$G$1,Actuals!A:A,">="&YTD!$G$3,Actuals!$F:$F,YTD!B11) -> 3000 | H11: =C11-G11 -> -2758.29
B12: Insurance | C12: =SUMIFS(Actuals!E:E,Actuals!A:A,"<="&YTD!$C$1,Actuals!A:A,">="&YTD!$C$3,Actuals!$F:$F,YTD!B12) -> 1089.47 | D12: =SUMIFS('2025 Budget'!S:S,'2025 Budget'!Q:Q,YTD!B12,'2025 Budget'!R:R,"<="&YTD!$C$1,'2025 Budget'!R:R,">="&YTD!$C$3) -> 1620 | E12: =C12-D12 -> -530.53 | G12: =SUMIFS(Actuals!E:E,Actuals!A:A,"<="&YTD!$G$1,Actuals!A:A,">="&YTD!$G$3,Actuals!$F:$F,YTD!B12) -> 1631.65 | H12: =C12-G12 -> -542.18
B13: Day Care | C13: =SUMIFS(Actuals!E:E,Actuals!A:A,"<="&YTD!$C$1,Actuals!A:A,">="&YTD!$C$3,Actuals!$F:$F,YTD!B13) -> 23875.18 | D13: =SUMIFS('2025 Budget'!S:S,'2025 Budget'!Q:Q,YTD!B13,'2025 Budget'!R:R,"<="&YTD!$C$1,'2025 Budget'!R:R,">="&YTD!$C$3) -> 27300 | E13: =C13-D13 -> -3424.82 | G13: =SUMIFS(Actuals!E:E,Actuals!A:A,"<="&YTD!$G$1,Actuals!A:A,">="&YTD!$G$3,Actuals!$F:$F,YTD!B13) -> 27362.99 | H13: =C13-G13 -> -3487.81
B14: Total Rent & Utilitites | C14: =SUM(C7:C13) -> 84532.41 | D14: =SUM(D7:D13) -> 77460 | E14: =C14-D14 -> 7072.41 | G14: =SUM(G7:G13) -> 77595.97 | H14: =C14-G14 -> 6936.44
B16: Transportation | C16: =SUMIFS(Actuals!E:E,Actuals!A:A,"<="&YTD!$C$1,Actuals!A:A,">="&YTD!$C$3,Actuals!$F:$F,YTD!B16) -> 4745.25 | D16: =SUMIFS('2025 Budget'!S:S,'2025 Budget'!Q:Q,YTD!B16,'2025 Budget'!R:R,"<="&YTD!$C$1,'2025 Budget'!R:R,">="&YTD!$C$3) -> 4800 | E16: =C16-D16 -> -54.75 | G16: =SUMIFS(Actuals!E:E,Actuals!A:A,"<="&YTD!$G$1,Actuals!A:A,">="&YTD!$G$3,Actuals!$F:$F,YTD!B16) -> 4295.84 | H16: =C16-G16 -> 449.41
B17: Restaurants | C17: =SUMIFS(Actuals!E:E,Actuals!A:A,"<="&YTD!$C$1,Actuals!A:A,">="&YTD!$C$3,Actuals!$F:$F,YTD!B17) -> 23100.66 | D17: =SUMIFS('2025 Budget'!S:S,'2025 Budget'!Q:Q,YTD!B17,'2025 Budget'!R:R,"<="&YTD!$C$1,'2025 Budget'!R:R,">="&YTD!$C$3) -> 15600 | E17: =C17-D17 -> 7500.66 | G17: =SUMIFS(Actuals!E:E,Actuals!A:A,"<="&YTD!$G$1,Actuals!A:A,">="&YTD!$G$3,Actuals!$F:$F,YTD!B17) -> 16610.65 | H17: =C17-G17 -> 6490.01
B18: Groceries | C18: =SUMIFS(Actuals!E:E,Actuals!A:A,"<="&YTD!$C$1,Actuals!A:A,">="&YTD!$C$3,Actuals!$F:$F,YTD!B18) -> 11355.96 | D18: =SUMIFS('2025 Budget'!S:S,'2025 Budget'!Q:Q,YTD!B18,'2025 Budget'!R:R,"<="&YTD!$C$1,'2025 Budget'!R:R,">="&YTD!$C$3) -> 12000 | E18: =C18-D18 -> -644.04 | G18: =SUMIFS(Actuals!E:E,Actuals!A:A,"<="&YTD!$G$1,Actuals!A:A,">="&YTD!$G$3,Actuals!$F:$F,YTD!B18) -> 11506.02 | H18: =C18-G18 -> -150.06
B19: Target | C19: =SUMIFS(Actuals!E:E,Actuals!A:A,"<="&YTD!$C$1,Actuals!A:A,">="&YTD!$C$3,Actuals!$F:$F,YTD!B19) -> 8438.87 | D19: =SUMIFS('2025 Budget'!S:S,'2025 Budget'!Q:Q,YTD!B19,'2025 Budget'!R:R,"<="&YTD!$C$1,'2025 Budget'!R:R,">="&YTD!$C$3) -> 8100 | E19: =C19-D19 -> 338.87 | G19: =SUMIFS(Actuals!E:E,Actuals!A:A,"<="&YTD!$G$1,Actuals!A:A,">="&YTD!$G$3,Actuals!$F:$F,YTD!B19) -> 8093.31 | H19: =C19-G19 -> 345.56
B20: Total Food & Car | C20: =SUM(C16:C19) -> 47640.74 | D20: =SUM(D16:D19) -> 40500 | E20: =SUM(E16:E19) -> 7140.74 | G20: =SUM(G16:G19) -> 40505.82 | H20: =C20-G20 -> 7134.92
B22: Gym | C22: =SUMIFS(Actuals!E:E,Actuals!A:A,"<="&YTD!$C$1,Actuals!A:A,">="&YTD!$C$3,Actuals!$F:$F,YTD!B22) -> 25 | D22: =SUMIFS('2025 Budget'!S:S,'2025 Budget'!Q:Q,YTD!B22,'2025 Budget'!R:R,"<="&YTD!$C$1,'2025 Budget'!R:R,">="&YTD!$C$3) -> 0 | E22: =C22-D22 -> 25 | G22: =SUMIFS(Actuals!E:E,Actuals!A:A,"<="&YTD!$G$1,Actuals!A:A,">="&YTD!$G$3,Actuals!$F:$F,YTD!B22) -> 381.52 | H22: =C22-G22 -> -356.52
B23: Shopping | C23: =SUMIFS(Actuals!E:E,Actuals!A:A,"<="&YTD!$C$1,Actuals!A:A,">="&YTD!$C$3,Actuals!$F:$F,YTD!B23) -> 21636.39 | D23: =SUMIFS('2025 Budget'!S:S,'2025 Budget'!Q:Q,YTD!B23,'2025 Budget'!R:R,"<="&YTD!$C$1,'2025 Budget'!R:R,">="&YTD!$C$3) -> 24000 | E23: =C23-D23 -> -2363.61 | G23: =SUMIFS(Actuals!E:E,Actuals!A:A,"<="&YTD!$G$1,Actuals!A:A,">="&YTD!$G$3,Actuals!$F:$F,YTD!B23) -> 24464.17 | H23: =C23-G23 -> -2827.78
B24: Amazon | C24: =SUMIFS(Actuals!E:E,Actuals!A:A,"<="&YTD!$C$1,Actuals!A:A,">="&YTD!$C$3,Actuals!$F:$F,YTD!B24) -> 5621.16 | D24: =SUMIFS('2025 Budget'!S:S,'2025 Budget'!Q:Q,YTD!B24,'2025 Budget'!R:R,"<="&YTD!$C$1,'2025 Budget'!R:R,">="&YTD!$C$3) -> 6960 | E24: =C24-D24 -> -1338.84 | G24: =SUMIFS(Actuals!E:E,Actuals!A:A,"<="&YTD!$G$1,Actuals!A:A,">="&YTD!$G$3,Actuals!$F:$F,YTD!B24) -> 7001.74 | H24: =C24-G24 -> -1380.58
B25: Entertainment | C25: =SUMIFS(Actuals!E:E,Actuals!A:A,"<="&YTD!$C$1,Actuals!A:A,">="&YTD!$C$3,Actuals!$F:$F,YTD!B25) -> 3681.42 | D25: =SUMIFS('2025 Budget'!S:S,'2025 Budget'!Q:Q,YTD!B25,'2025 Budget'!R:R,"<="&YTD!$C$1,'2025 Budget'!R:R,">="&YTD!$C$3) -> 6600 | E25: =C25-D25 -> -2918.58 | G25: =SUMIFS(Actuals!E:E,Actuals!A:A,"<="&YTD!$G$1,Actuals!A:A,">="&YTD!$G$3,Actuals!$F:$F,YTD!B25) -> 7135.13 | H25: =C25-G25 -> -3453.71
B26: Dry Cleaning | C26: =SUMIFS(Actuals!E:E,Actuals!A:A,"<="&YTD!$C$1,Actuals!A:A,">="&YTD!$C$3,Actuals!$F:$F,YTD!B26) -> 406.58 | D26: =SUMIFS('2025 Budget'!S:S,'2025 Budget'!Q:Q,YTD!B26,'2025 Budget'!R:R,"<="&YTD!$C$1,'2025 Budget'!R:R,">="&YTD!$C$3) -> 540 | E26: =C26-D26 -> -133.42 | G26: =SUMIFS(Actuals!E:E,Actuals!A:A,"<="&YTD!$G$1,Actuals!A:A,">="&YTD!$G$3,Actuals!$F:$F,YTD!B26) -> 537.86 | H26: =C26-G26 -> -131.28
B27: Gifts | C27: =SUMIFS(Actuals!E:E,Actuals!A:A,"<="&YTD!$C$1,Actuals!A:A,">="&YTD!$C$3,Actuals!$F:$F,YTD!B27) -> 594.78 | D27: =SUMIFS('2025 Budget'!S:S,'2025 Budget'!Q:Q,YTD!B27,'2025 Budget'!R:R,"<="&YTD!$C$1,'2025 Budget'!R:R,">="&YTD!$C$3) -> 1200 | E27: =C27-D27 -> -605.22 | G27: =SUMIFS(Actuals!E:E,Actuals!A:A,"<="&YTD!$G$1,Actuals!A:A,">="&YTD!$G$3,Actuals!$F:$F,YTD!B27) -> 780.65 | H27: =C27-G27 -> -185.87
B28: Misc | C28: =SUMIFS(Actuals!E:E,Actuals!A:A,"<="&YTD!$C$1,Actuals!A:A,">="&YTD!$C$3,Actuals!$F:$F,YTD!B28) -> 421.02 | D28: =SUMIFS('2025 Budget'!S:S,'2025 Budget'!Q:Q,YTD!B28,'2025 Budget'!R:R,"<="&YTD!$C$1,'2025 Budget'!R:R,">="&YTD!$C$3) -> 540 | E28: =C28-D28 -> -118.98 | G28: =SUMIFS(Actuals!E:E,Actuals!A:A,"<="&YTD!$G$1,Actuals!A:A,">="&YTD!$G$3,Actuals!$F:$F,YTD!B28) -> 527.85 | H28: =C28-G28 -> -106.83
B29: Total Other | C29: =SUM(C22:C28) -> 32386.35 | D29: =SUM(D22:D28) -> 39840 | E29: =C29-D29 -> -7453.65 | G29: =SUM(G22:G28) -> 40828.92 | H29: =C29-G29 -> -8442.57
B31: Total | C31: =SUM(C29,C20,C14) -> 164559.5 | D31: =SUM(D29,D20,D14) -> 157800 | E31: =C31-D31 -> 6759.5 | G31: =SUM(G29,G20,G14) -> 158930.71 | H31: =C31-G31 -> 5628.79
B33: Healthcare | C33: =SUMIFS(Actuals!E:E,Actuals!A:A,"<="&YTD!$C$1,Actuals!A:A,">="&YTD!$C$3,Actuals!$F:$F,YTD!B33) -> 3948.01 | G33: =SUMIFS(Actuals!E:E,Actuals!A:A,"<="&YTD!$G$1,Actuals!A:A,">="&YTD!$G$3,Actuals!$F:$F,YTD!B33) -> 2527.44 | H33: =C33-G33 -> 1420.57
B34: House | C34: =SUMIFS(Actuals!E:E,Actuals!A:A,"<="&YTD!$C$1,Actuals!A:A,">="&YTD!$C$3,Actuals!$F:$F,YTD!B34) -> 265799.33 | G34: =SUMIFS(Actuals!E:E,Actuals!A:A,"<="&YTD!$G$1,Actuals!A:A,">="&YTD!$G$3,Actuals!$F:$F,YTD!B34) -> 11572.24 | H34: =C34-G34 -> 254227.09
B35: Travel | C35: =SUMIFS(Actuals!E:E,Actuals!A:A,"<="&YTD!$C$1,Actuals!A:A,">="&YTD!$C$3,Actuals!$F:$F,YTD!B35) -> 16470.36 | G35: =SUMIFS(Actuals!E:E,Actuals!A:A,"<="&YTD!$G$1,Actuals!A:A,">="&YTD!$G$3,Actuals!$F:$F,YTD!B35) -> 18097.97 | H35: =C35-G35 -> -1627.61
B36: Total | C36: =SUM(C33:C35) -> 286217.7 | G36: =SUM(G33:G35) -> 32197.65 | H36: =C36-G36 -> 254020.05
G37: =SUMIFS(Actuals!E:E,Actuals!A:A,"<="&YTD!$G$1,Actuals!A:A,">="&YTD!$G$3,Actuals!$F:$F,YTD!B37) -> 0 | H37: =C37-G37 -> 0
B38: Total Spend | C38: =SUM(C36,C31) -> 450777.2 | G38: =SUM(G36,G31) -> 191128.36 | H38: =C38-G38 -> 259648.84

Sheet 2025 Budget
B1: Values here pull into the monthy reporting for actual vs budget reporting
B3: Budget | C3: 202501 | D3: 202502 | E3: 202503 | F3: 202504 | G3: 202505 | H3: 202506 | I3: 202507 | J3: 202508 | K3: 202509 | L3: 202510 | M3: 202511 | N3: 202512 | O3: Total
B5: Rent | C5: 2745 | D5: 2745 | E5: 2745 | F5: 2745 | G5: 2745 | H5: 2745 | I5: 2745 | J5: 2745 | K5: 2745 | L5: 2745 | M5: 2745 | N5: 2745 | O5: =SUM(C5:N5) -> 32940 | Q5: Rent | R5: =$C$3 -> 202501 | S5: =INDEX($B$3:$O$36,MATCH(Q5,$B$3:$B$36,0),MATCH(R5,$B$3:$O$3,0)) -> 2745
B6: House Maintenance | C6: 350 | D6: 350 | E6: 350 | F6: 350 | G6: 350 | H6: 350 | I6: 350 | J6: 350 | K6: 350 | L6: 350 | M6: 350 | N6: 350 | O6: =SUM(C6:N6) -> 4200 | Q6: House Maintenance | R6: =$C$3 -> 202501 | S6: =INDEX($B$3:$O$36,MATCH(Q6,$B$3:$B$36,0),MATCH(R6,$B$3:$O$3,0)) -> 350
B7: Utilities | C7: 700 | D7: 700 | E7: 700 | F7: 700 | G7: 700 | H7: 700 | I7: 700 | J7: 700 | K7: 700 | L7: 700 | M7: 700 | N7: 700 | O7: =SUM(C7:N7) -> 8400 | Q7: Utilities | R7: =$C$3 -> 202501 | S7: =INDEX($B$3:$O$36,MATCH(Q7,$B$3:$B$36,0),MATCH(R7,$B$3:$O$3,0)) -> 700
B8: Car Loan | O8: =SUM(C8:N8) -> 0 | Q8: Car Loan | R8: =$C$3 -> 202501 | S8: =INDEX($B$3:$O$36,MATCH(Q8,$B$3:$B$36,0),MATCH(R8,$B$3:$O$3,0)) -> 0
B9: Cleaning | C9: =125*2 -> 250 | D9: =125*2 -> 250 | E9: =125*2 -> 250 | F9: =125*2 -> 250 | G9: =125*2 -> 250 | H9: =125*2 -> 250 | I9: =125*2 -> 250 | J9: =125*2 -> 250 | ... N9: =125*2 -> 250 | O9: =SUM(C9:N9) -> 3000 | Q9: Cleaning | R9: =$C$3 -> 202501 | S9: =INDEX($B$3:$O$36,MATCH(Q9,$B$3:$B$36,0),MATCH(R9,$B$3:$O$3,0)) -> 250
B10: Insurance | C10: 135 | D10: 135 | E10: 135 | F10: 135 | G10: 135 | H10: 135 | I10: 135 | J10: 135 | K10: 135 | L10: 135 | M10: 135 | N10: 135 | O10: =SUM(C10:N10) -> 1620 | Q10: Insurance | R10: =$C$3 -> 202501 | S10: =INDEX($B$3:$O$36,MATCH(Q10,$B$3:$B$36,0),MATCH(R10,$B$3:$O$3,0)) -> 135
B11: Day Care | C11: 2275 | D11: 2275 | E11: 2275 | F11: 2275 | G11: 2275 | H11: 2275 | I11: 2275 | J11: 2275 | K11: 2275 | L11: 2275 | M11: 2275 | N11: 2275 | O11: =SUM(C11:N11) -> 27300 | Q11: Day Care | R11: =$C$3 -> 202501 | S11: =INDEX($B$3:$O$36,MATCH(Q11,$B$3:$B$36,0),MATCH(R11,$B$3:$O$3,0)) -> 2275
B12: Total Rent & Utilitites | C12: =SUM(C5:C11) -> 6455 | D12: =SUM(D5:D11) -> 6455 | E12: =SUM(E5:E11) -> 6455 | F12: =SUM(F5:F11) -> 6455 | G12: =SUM(G5:G11) -> 6455 | H12: =SUM(H5:H11) -> 6455 | I12: =SUM(I5:I11) -> 6455 | J12: =SUM(J5:J11) -> 6455 | ... N12: =SUM(N5:N11) -> 6455 | O12: =SUM(C12:N12) -> 77460 | Q12: Total Rent & Utilitites | R12: =$C$3 -> 202501 | S12: =INDEX($B$3:$O$36,MATCH(Q12,$B$3:$B$36,0),MATCH(R12,$B$3:$O$3,0)) -> 6455
R13: =$C$3 -> 202501 | S13: =INDEX($B$3:$O$36,MATCH(Q13,$B$3:$B$36,0),MATCH(R13,$B$3:$O$3,0)) -> #N/A
B14: Transportation | C14: 400 | D14: 400 | E14: 400 | F14: 400 | G14: 400 | H14: 400 | I14: 400 | J14: 400 | K14: 400 | L14: 400 | M14: 400 | N14: 400 | O14: =SUM(C14:N14) -> 4800 | Q14: Transportation | R14: =$C$3 -> 202501 | S14: =INDEX($B$3:$O$36,MATCH(Q14,$B$3:$B$36,0),MATCH(R14,$B$3:$O$3,0)) -> 400
B15: Restaurants | C15: 1300 | D15: 1300 | E15: 1300 | F15: 1300 | G15: 1300 | H15: 1300 | I15: 1300 | J15: 1300 | K15: 1300 | L15: 1300 | M15: 1300 | N15: 1300 | O15: =SUM(C15:N15) -> 15600 | Q15: Restaurants | R15: =$C$3 -> 202501 | S15: =INDEX($B$3:$O$36,MATCH(Q15,$B$3:$B$36,0),MATCH(R15,$B$3:$O$3,0)) -> 1300
B16: Groceries | C16: 1000 | D16: 1000 | E16: 1000 | F16: 1000 | G16: 1000 | H16: 1000 | I16: 1000 | J16: 1000 | K16: 1000 | L16: 1000 | M16: 1000 | N16: 1000 | O16: =SUM(C16:N16) -> 12000 | Q16: Groceries | R16: =$C$3 -> 202501 | S16: =INDEX($B$3:$O$36,MATCH(Q16,$B$3:$B$36,0),MATCH(R16,$B$3:$O$3,0)) -> 1000
B17: Target | C17: 675 | D17: 675 | E17: 675 | F17: 675 | G17: 675 | H17: 675 | I17: 675 | J17: 675 | K17: 675 | L17: 675 | M17: 675 | N17: 675 | O17: =SUM(C17:N17) -> 8100 | Q17: Target | R17: =$C$3 -> 202501 | S17: =INDEX($B$3:$O$36,MATCH(Q17,$B$3:$B$36,0),MATCH(R17,$B$3:$O$3,0)) -> 675
B18: Total Food & Car | C18: =SUM(C14:C17) -> 3375 | D18: =SUM(D14:D17) -> 3375 | E18: =SUM(E14:E17) -> 3375 | F18: =SUM(F14:F17) -> 3375 | G18: =SUM(G14:G17) -> 3375 | H18: =SUM(H14:H17) -> 3375 | I18: =SUM(I14:I17) -> 3375 | J18: =SUM(J14:J17) -> 3375 | ... N18: =SUM(N14:N17) -> 3375 | O18: =SUM(C18:N18) -> 40500 | Q18: Total Food & Car | R18: =$C$3 -> 202501 | S18: =INDEX($B$3:$O$36,MATCH(Q18,$B$3:$B$36,0),MATCH(R18,$B$3:$O$3,0)) -> 3375
R19: =$C$3 -> 202501 | S19: =INDEX($B$3:$O$36,MATCH(Q19,$B$3:$B$36,0),MATCH(R19,$B$3:$O$3,0)) -> #N/A
B20: Gym | C20: 0 | D20: 0 | E20: 0 | F20: 0 | G20: 0 | H20: 0 | I20: 0 | J20: 0 | K20: 0 | L20: 0 | M20: 0 | N20: 0 | O20: =SUM(C20:N20) -> 0 | Q20: Gym | R20: =$C$3 -> 202501 | S20: =INDEX($B$3:$O$36,MATCH(Q20,$B$3:$B$36,0),MATCH(R20,$B$3:$O$3,0)) -> 0
B21: Shopping | C21: 2000 | D21: 2000 | E21: 2000 | F21: 2000 | G21: 2000 | H21: 2000 | I21: 2000 | J21: 2000 | K21: 2000 | L21: 2000 | M21: 2000 | N21: 2000 | O21: =SUM(C21:N21) -> 24000 | Q21: Shopping | R21: =$C$3 -> 202501 | S21: =INDEX($B$3:$O$36,MATCH(Q21,$B$3:$B$36,0),MATCH(R21,$B$3:$O$3,0)) -> 2000
B22: Amazon | C22: 580 | D22: 580 | E22: 580 | F22: 580 | G22: 580 | H22: 580 | I22: 580 | J22: 580 | K22: 580 | L22: 580 | M22: 580 | N22: 580 | O22: =SUM(C22:N22) -> 6960 | Q22: Amazon | R22: =$C$3 -> 202501 | S22: =INDEX($B$3:$O$36,MATCH(Q22,$B$3:$B$36,0),MATCH(R22,$B$3:$O$3,0)) -> 580
B23: Entertainment | C23: 550 | D23: 550 | E23: 550 | F23: 550 | G23: 550 | H23: 550 | I23: 550 | J23: 550 | K23: 550 | L23: 550 | M23: 550 | N23: 550 | O23: =SUM(C23:N23) -> 6600 | Q23: Entertainment | R23: =$C$3 -> 202501 | S23: =INDEX($B$3:$O$36,MATCH(Q23,$B$3:$B$36,0),MATCH(R23,$B$3:$O$3,0)) -> 550
B24: Dry Cleaning | C24: 45 | D24: 45 | E24: 45 | F24: 45 | G24: 45 | H24: 45 | I24: 45 | J24: 45 | K24: 45 | L24: 45 | M24: 45 | N24: 45 | O24: =SUM(C24:N24) -> 540 | Q24: Dry Cleaning | R24: =$C$3 -> 202501 | S24: =INDEX($B$3:$O$36,MATCH(Q24,$B$3:$B$36,0),MATCH(R24,$B$3:$O$3,0)) -> 45
B25: Gifts | C25: 100 | D25: 100 | E25: 100 | F25: 100 | G25: 100 | H25: 100 | I25: 100 | J25: 100 | K25: 100 | L25: 100 | M25: 100 | N25: 100 | O25: =SUM(C25:N25) -> 1200 | Q25: Gifts | R25: =$C$3 -> 202501 | S25: =INDEX($B$3:$O$36,MATCH(Q25,$B$3:$B$36,0),MATCH(R25,$B$3:$O$3,0)) -> 100
B26: Misc | C26: 45 | D26: 45 | E26: 45 | F26: 45 | G26: 45 | H26: 45 | I26: 45 | J26: 45 | K26: 45 | L26: 45 | M26: 45 | N26: 45 | O26: =SUM(C26:N26) -> 540 | Q26: Misc | R26: =$C$3 -> 202501 | S26: =INDEX($B$3:$O$36,MATCH(Q26,$B$3:$B$36,0),MATCH(R26,$B$3:$O$3,0)) -> 45
B27: Total Other | C27: =SUM(C20:C26) -> 3320 | D27: =SUM(D20:D26) -> 3320 | E27: =SUM(E20:E26) -> 3320 | F27: =SUM(F20:F26) -> 3320 | G27: =SUM(G20:G26) -> 3320 | H27: =SUM(H20:H26) -> 3320 | I27: =SUM(I20:I26) -> 3320 | J27: =SUM(J20:J26) -> 3320 | ... N27: =SUM(N20:N26) -> 3320 | O27: =SUM(C27:N27) -> 39840 | Q27: Total Other | R27: =$C$3 -> 202501 | S27: =INDEX($B$3:$O$36,MATCH(Q27,$B$3:$B$36,0),MATCH(R27,$B$3:$O$3,0)) -> 3320
O28: =SUM(C28:N28) -> 0 | R28: =$C$3 -> 202501 | S28: =INDEX($B$3:$O$36,MATCH(Q28,$B$3:$B$36,0),MATCH(R28,$B$3:$O$3,0)) -> #N/A
B29: Total | C29: =SUM(C27,C18,C12) -> 13150 | D29: =SUM(D27,D18,D12) -> 13150 | E29: =SUM(E27,E18,E12) -> 13150 | F29: =SUM(F27,F18,F12) -> 13150 | G29: =SUM(G27,G18,G12) -> 13150 | H29: =SUM(H27,H18,H12) -> 13150 | I29: =SUM(I27,I18,I12) -> 13150 | J29: =SUM(J27,J18,J12) -> 13150 | ... N29: =SUM(N27,N18,N12) -> 13150 | O29: =SUM(C29:N29) -> 157800 | Q29: Total | R29: =$C$3 -> 202501 | S29: =INDEX($B$3:$O$36,MATCH(Q29,$B$3:$B$36,0),MATCH(R29,$B$3:$O$3,0)) -> 13150
R30: =$C$3 -> 202501 | S30: =INDEX($B$3:$O$36,MATCH(Q30,$B$3:$B$36,0),MATCH(R30,$B$3:$O$3,0)) -> #N/A
B31: Healthcare | C31: 200 | D31: 200 | E31: 200 | F31: 200 | G31: 200 | H31: 200 | I31: 200 | J31: 200 | K31: 200 | L31: 200 | M31: 200 | N31: 200 | O31: =SUM(C31:N31) -> 2400 | Q31: Healthcare | R31: =$C$3 -> 202501 | S31: =INDEX($B$3:$O$36,MATCH(Q31,$B$3:$B$36,0),MATCH(R31,$B$3:$O$3,0)) -> 200
B32: House | C32: =30245 -> 30245 | D32: 19919.5 | E32: 13299.5 | F32: 17668 | O32: =SUM(C32:N32) -> 81132 | Q32: House | R32: =$C$3 -> 202501 | S32: =INDEX($B$3:$O$36,MATCH(Q32,$B$3:$B$36,0),MATCH(R32,$B$3:$O$3,0)) -> 30245
B33: Travel | E33: 2000 | F33: 4000 | H33: 1500 | K33: 2000 | L33: 2000 | M33: 2000 | O33: =SUM(C33:N33) -> 13500 | Q33: Travel | R33: =$C$3 -> 202501 | S33: =INDEX($B$3:$O$36,MATCH(Q33,$B$3:$B$36,0),MATCH(R33,$B$3:$O$3,0)) -> 0
B34: Total Yearly | C34: =SUM(C31:C33) -> 30445 | D34: =SUM(D31:D33) -> 20119.5 | E34: =SUM(E31:E33) -> 15499.5 | F34: =SUM(F31:F33) -> 21868 | G34: =SUM(G31:G33) -> 200 | H34: =SUM(H31:H33) -> 1700 | I34: =SUM(I31:I33) -> 200 | J34: =SUM(J31:J33) -> 200 | ... O34: =SUM(O31:O33) -> 97032 | Q34: Total Yearly | R34: =$C$3 -> 202501 | S34: =INDEX($B$3:$O$36,MATCH(Q34,$B$3:$B$36,0),MATCH(R34,$B$3:$O$3,0)) -> 30445
R35: =$C$3 -> 202501 | S35: =INDEX($B$3:$O$36,MATCH(Q35,$B$3:$B$36,0),MATCH(R35,$B$3:$O$3,0)) -> #N/A
B36: Total All Spend | C36: =SUM(C34,C29) -> 43595 | D36: =SUM(D34,D29) -> 33269.5 | E36: =SUM(E34,E29) -> 28649.5 | F36: =SUM(F34,F29) -> 35018 | G36: =SUM(G34,G29) -> 13350 | H36: =SUM(H34,H29) -> 14850 | I36: =SUM(I34,I29) -> 13350 | J36: =SUM(J34,J29) -> 13350 | ... O36: =SUM(O34,O29) -> 254832 | Q36: Total All Spend | R36: =$C$3 -> 202501 | S36: =INDEX($B$3:$O$36,MATCH(Q36,$B$3:$B$36,0),MATCH(R36,$B$3:$O$3,0)) -> 43595
Q37: Rent | R37: =$D$3 -> 202502 | S37: =INDEX($B$3:$O$36,MATCH(Q37,$B$3:$B$36,0),MATCH(R37,$B$3:$O$3,0)) -> 2745
Q38: House Maintenance | R38: =$D$3 -> 202502 | S38: =INDEX($B$3:$O$36,MATCH(Q38,$B$3:$B$36,0),MATCH(R38,$B$3:$O$3,0)) -> 350
B39: Budget | C39: 202401 | D39: 202402 | E39: 202403 | F39: 202404 | G39: 202405 | H39: 202406 | I39: 202407 | J39: 202408 | K39: 202409 | L39: 202410 | M39: 202411 | N39: 202412 | O39: Total | Q39: Utilities | R39: =$D$3 -> 202502 | S39: =INDEX($B$3:$O$36,MATCH(Q39,$B$3:$B$36,0),MATCH(R39,$B$3:$O$3,0)) -> 700
Q40: Car Loan | R40: =$D$3 -> 202502 | S40: =INDEX($B$3:$O$36,MATCH(Q40,$B$3:$B$36,0),MATCH(R40,$B$3:$O$3,0)) -> 0
B41: Rent | C41: 2572.94 | D41: 2572.94 | E41: 2572.94 | F41: 2572.94 | G41: 2572.94 | H41: 2572.94 | I41: 2572.94 | J41: 2572.94 | K41: 2572.94 | L41: 2572.94 | M41: 2572.94 | N41: 2572.94 | O41: =SUM(C41:N41) -> 30875.28 | Q41: Cleaning | R41: =$D$3 -> 202502 | S41: =INDEX($B$3:$O$36,MATCH(Q41,$B$3:$B$36,0),MATCH(R41,$B$3:$O$3,0)) -> 250
B42: House Maintenance | C42: 500 | D42: 500 | E42: 500 | F42: 500 | G42: 500 | H42: 500 | I42: 500 | J42: 500 | K42: 500 | L42: 500 | M42: 500 | N42: 500 | O42: =SUM(C42:N42) -> 6000 | Q42: Insurance | R42: =$D$3 -> 202502 | S42: =INDEX($B$3:$O$36,MATCH(Q42,$B$3:$B$36,0),MATCH(R42,$B$3:$O$3,0)) -> 135
...

Sheet Year
D1: =VALUE('1 MO'!$C$3&"01") -> 202501 | E1: =VALUE('1 MO'!$C$3&"02") -> 202502 | F1: =VALUE('1 MO'!$C$3&"03") -> 202503 | G1: =VALUE('1 MO'!$C$3&"04") -> 202504 | H1: =VALUE('1 MO'!$C$3&"05") -> 202505 | I1: =VALUE('1 MO'!$C$3&"06") -> 202506 | J1: =VALUE('1 MO'!$C$3&"07") -> 202507 | K1: =VALUE('1 MO'!$C$3&"08") -> 202508 | L1: =VALUE('1 MO'!$C$3&"09") -> 202509 | M1: =VALUE('1 MO'!$C$3&"10") -> 202510 | N1: =VALUE('1 MO'!$C$3&"11") -> 202511 | O1: =VALUE('1 MO'!$C$3&"12") -> 202512
C7: Actuals | D7: =TEXT(DATE(LEFT(D1,4),RIGHT(D1,2),1),"MMM YYYY") -> Jan 2025 | E7: =TEXT(DATE(LEFT(E1,4),RIGHT(E1,2),1),"MMM YYYY") -> Feb 2025 | F7: =TEXT(DATE(LEFT(F1,4),RIGHT(F1,2),1),"MMM YYYY") -> Mar 2025 | G7: =TEXT(DATE(LEFT(G1,4),RIGHT(G1,2),1),"MMM YYYY") -> Apr 2025 | H7: =TEXT(DATE(LEFT(H1,4),RIGHT(H1,2),1),"MMM YYYY") -> May 2025 | I7: =TEXT(DATE(LEFT(I1,4),RIGHT(I1,2),1),"MMM YYYY") -> Jun 2025 | J7: =TEXT(DATE(LEFT(J1,4),RIGHT(J1,2),1),"MMM YYYY") -> Jul 2025 | K7: =TEXT(DATE(LEFT(K1,4),RIGHT(K1,2),1),"MMM YYYY") -> Aug 2025 | ... O7: =TEXT(DATE(LEFT(O1,4),RIGHT(O1,2),1),"MMM YYYY") -> Dec 2025 | P7: Total | R7: 2024 | S7: 2023 | T7: Dif
C9: Rent | D9: =SUMIFS(Actuals!$E:$E,Actuals!$F:$F,Year!$C9,Actuals!$A:$A,Year!D$1) -> 2745.43 | E9: =SUMIFS(Actuals!$E:$E,Actuals!$F:$F,Year!$C9,Actuals!$A:$A,Year!E$1) -> 2745.43 | F9: =SUMIFS(Actuals!$E:$E,Actuals!$F:$F,Year!$C9,Actuals!$A:$A,Year!F$1) -> 1770.04 | G9: =SUMIFS(Actuals!$E:$E,Actuals!$F:$F,Year!$C9,Actuals!$A:$A,Year!G$1) -> 2745.43 | H9: =SUMIFS(Actuals!$E:$E,Actuals!$F:$F,Year!$C9,Actuals!$A:$A,Year!H$1) -> 2745.43 | I9: =SUMIFS(Actuals!$E:$E,Actuals!$F:$F,Year!$C9,Actuals!$A:$A,Year!I$1) -> 2745.43 | J9: =SUMIFS(Actuals!$E:$E,Actuals!$F:$F,Year!$C9,Actuals!$A:$A,Year!J$1) -> 2745.43 | K9: =SUMIFS(Actuals!$E:$E,Actuals!$F:$F,Year!$C9,Actuals!$A:$A,Year!K$1) -> 2745.43 | ... O9: =SUMIFS(Actuals!$E:$E,Actuals!$F:$F,Year!$C9,Actuals!$A:$A,Year!O$1) -> 3378.51 | P9: =SUM(D9:O9) -> 34502.09 | R9: 32915.64 | S9: 31817.12 | T9: =R9-S9 -> 1098.52
C10: House Maintenance | D10: =SUMIFS(Actuals!$E:$E,Actuals!$F:$F,Year!$C10,Actuals!$A:$A,Year!D$1) -> 158.51 | E10: =SUMIFS(Actuals!$E:$E,Actuals!$F:$F,Year!$C10,Actuals!$A:$A,Year!E$1) -> 72.41 | F10: =SUMIFS(Actuals!$E:$E,Actuals!$F:$F,Year!$C10,Actuals!$A:$A,Year!F$1) -> 432.06 | G10: =SUMIFS(Actuals!$E:$E,Actuals!$F:$F,Year!$C10,Actuals!$A:$A,Year!G$1) -> 532.52 | H10: =SUMIFS(Actuals!$E:$E,Actuals!$F:$F,Year!$C10,Actuals!$A:$A,Year!H$1) -> 296.68 | I10: =SUMIFS(Actuals!$E:$E,Actuals!$F:$F,Year!$C10,Actuals!$A:$A,Year!I$1) -> 719.26 | J10: =SUMIFS(Actuals!$E:$E,Actuals!$F:$F,Year!$C10,Actuals!$A:$A,Year!J$1) -> 373.78 | K10: =SUMIFS(Actuals!$E:$E,Actuals!$F:$F,Year!$C10,Actuals!$A:$A,Year!K$1) -> 127.46 | ... O10: =SUMIFS(Actuals!$E:$E,Actuals!$F:$F,Year!$C10,Actuals!$A:$A,Year!O$1) -> 32.64 | P10: =SUM(D10:O10) -> 4152.49 | R10: 4195.69 | S10: 6575 | T10: =R10-S10 -> -2379.31
C11: Utilities | D11: =SUMIFS(Actuals!$E:$E,Actuals!$F:$F,Year!$C11,Actuals!$A:$A,Year!D$1) -> 512.23 | E11: =SUMIFS(Actuals!$E:$E,Actuals!$F:$F,Year!$C11,Actuals!$A:$A,Year!E$1) -> 1454.37 | F11: =SUMIFS(Actuals!$E:$E,Actuals!$F:$F,Year!$C11,Actuals!$A:$A,Year!F$1) -> 404.52 | G11: =SUMIFS(Actuals!$E:$E,Actuals!$F:$F,Year!$C11,Actuals!$A:$A,Year!G$1) -> 507.12 | H11: =SUMIFS(Actuals!$E:$E,Actuals!$F:$F,Year!$C11,Actuals!$A:$A,Year!H$1) -> 726.93 | I11: =SUMIFS(Actuals!$E:$E,Actuals!$F:$F,Year!$C11,Actuals!$A:$A,Year!I$1) -> 2595.93 | J11: =SUMIFS(Actuals!$E:$E,Actuals!$F:$F,Year!$C11,Actuals!$A:$A,Year!J$1) -> 2949.64 | K11: =SUMIFS(Actuals!$E:$E,Actuals!$F:$F,Year!$C11,Actuals!$A:$A,Year!K$1) -> 744.52 | ... O11: =SUMIFS(Actuals!$E:$E,Actuals!$F:$F,Year!$C11,Actuals!$A:$A,Year!O$1) -> 1190.87 | P11: =SUM(D11:O11) -> 20671.47 | R11: 8490 | S11: 5694.76 | T11: =R11-S11 -> 2795.24
C12: Car Loan | D12: =SUMIFS(Actuals!$E:$E,Actuals!$F:$F,Year!$C12,Actuals!$A:$A,Year!D$1) -> 0 | E12: =SUMIFS(Actuals!$E:$E,Actuals!$F:$F,Year!$C12,Actuals!$A:$A,Year!E$1) -> 0 | F12: =SUMIFS(Actuals!$E:$E,Actuals!$F:$F,Year!$C12,Actuals!$A:$A,Year!F$1) -> 0 | G12: =SUMIFS(Actuals!$E:$E,Actuals!$F:$F,Year!$C12,Actuals!$A:$A,Year!G$1) -> 0 | H12: =SUMIFS(Actuals!$E:$E,Actuals!$F:$F,Year!$C12,Actuals!$A:$A,Year!H$1) -> 0 | I12: =SUMIFS(Actuals!$E:$E,Actuals!$F:$F,Year!$C12,Actuals!$A:$A,Year!I$1) -> 0 | J12: =SUMIFS(Actuals!$E:$E,Actuals!$F:$F,Year!$C12,Actuals!$A:$A,Year!J$1) -> 0 | K12: =SUMIFS(Actuals!$E:$E,Actuals!$F:$F,Year!$C12,Actuals!$A:$A,Year!K$1) -> 0 | ... O12: =SUMIFS(Actuals!$E:$E,Actuals!$F:$F,Year!$C12,Actuals!$A:$A,Year!O$1) -> 0 | P12: =SUM(D12:O12) -> 0 | R12: 0 | S12: 6186.5 | T12: =R12-S12 -> -6186.5
